Workbook

Sheet DASHBOARD
B2: PANEL DE ANÁLISIS — EMPLEO JUVENIL EN ARGENTINA (EPH · INDEC)
B3: Segmento 18 a 29 años · EPH 2025 · trimestre 1 · elaborado por Jeisson Marín Uribe para Fundación Impacto Laboral · actualizado 18/09/2026
B5: Jóvenes 18-29 relevados | F5: Tasa de desocupación juvenil | J5: Informalidad (sin aportes)
B6: =COUNTA('Jóvenes_18_29'!$A$2:$A$5934) | F6: =COUNTIF('Jóvenes_18_29'!$M$2:$M$5934,2)/(COUNTIF('Jóvenes_18_29'!$M$2:$M$5934,1)+COUNTIF('Jóvenes_18_29'!$M$2:$M$5934,2)) | J6: =AVERAGE('Jóvenes_18_29'!$AA$2:$AA$5934)
B8: IPL promedio (0 a 3) | F8: Ingreso promedio ocupados | J8: Correlación ISE ↔ IPL
B9: =AVERAGE('Jóvenes_18_29'!$AD$2:$AD$5934) | F9: =AVERAGE('Jóvenes_18_29'!$AH$2:$AH$5934) | J9: =Correlacion!F7
B11: Gráfico 1 — Matriz de calor de correlación | H11: Gráfico 2 — Brecha de género en precariedad, por región
B33: Gráfico 3 — Ingreso y precariedad según nivel educativo | H33: Cómo leer este panel
H34: · 58.1% de los jóvenes ocupados trabaja sin aportes jubilatorios.
H35: · El IPL promedio es 1.72 sobre 3 y 32.9% acumula las tres carencias.
H36: · Las mujeres registran un IPL de 1.78 frente a 1.67 de los varones (brecha +0.11).
H37: · La brecha de género más alta se observa en Patagonia (+0.42).
H38: · Correlación ISE ↔ IPL = -0.365: la educación es el principal amortiguador de la precariedad.
H39: · Todas las celdas son fórmulas vivas: al reemplazar el archivo de microdatos, el panel se recalcula solo.
H40: · Para agregar segmentadores interactivos: Insertar → Tabla dinámica sobre la hoja de trabajo y luego Analizar → Insertar segmentación de datos (REGION_TEXTO y TRAMO_EDAD).

Sheet Tablas_Equivalencia
A1: Tablas de equivalencia — Diseño de Registro EPH (INDEC)
A2: REGION | B2: Etiqueta | D2: NIVEL_ED | E2: Etiqueta | G2: ESTADO | H2: Etiqueta
A3: 1 | B3: Gran Buenos Aires | D3: 1 | E3: Primaria incompleta | G3: 1 | H3: Ocupado
A4: 40 | B4: Noroeste (NOA) | D4: 2 | E4: Primaria completa | G4: 2 | H4: Desocupado
A5: 41 | B5: Noreste (NEA) | D5: 3 | E5: Secundaria incompleta | G5: 3 | H5: Inactivo
A6: 42 | B6: Cuyo | D6: 4 | E6: Secundaria completa | G6: 4 | H6: Menor de 10 años
A7: 43 | B7: Pampeana | D7: 5 | E7: Superior incompleto
A8: 44 | B8: Patagonia | D8: 6 | E8: Superior completo
D9: 7 | E9: Sin instrucción
A12: Recordatorio metodológico: PP07H = 2 indica que NO le descuentan aportes jubilatorios (empleo informal); PP07C ≥ 2 indica inestabilidad contractual; PP3E_TOT = 999 es Ns./Nr.; P21 = -9 es no respuesta de ingresos.

Sheet Jóvenes_18_29
A1: CODUSU | B1: ANO4 | C1: TRIMESTRE | D1: REGION | E1: MAS_500 | F1: AGLOMERADO | G1: PONDERA | H1: CH03 | I1: CH04 | J1: CH06 | K1: CH10 | L1: NIVEL_ED | M1: ESTADO | N1: CAT_OCUP | O1: PP07C | P1: PP07H | Q1: PP3E_TOT | R1: P21 | S1: TOT_P12 | T1: P47T | U1: IPCF | V1: REGION_TEXTO | W1: NIVEL_ED_TEXTO | X1: SEXO_TEXTO | Y1: ESTADO_TEXTO | Z1: TRAMO_EDAD | AA1: IPL_Jubilacion | AB1: IPL_Inestabilidad | AC1: IPL_Jornada | AD1: IPL | AE1: ISE_NivelJoven | AF1: ISE_Hogar | AG1: ISE | AH1: P21_LIMPIO | AI1: HORAS_LIMPIO
A2: TQRMNOP100001 | B2: 2025 | C2: 1 | D2: 42 | E2: N | F2: 27 | G2: 1195 | H2: 1 | I2: 2 | J2: 18 | K2: 1 | L2: 5 | M2: 1 | N2: 3 | O2: 1 | P2: 1 | Q2: 44 | R2: -9 | S2: 0 | T2: 0 | U2: 46800 | V2: =IFERROR(VLOOKUP(D2,Tablas_Equivalencia!$A$3:$B$8,2,FALSE),"Sin dato") | W2: =IFERROR(VLOOKUP(L2,Tablas_Equivalencia!$D$3:$E$9,2,FALSE),"Sin dato") | X2: =IF(I2=1,"Varón","Mujer") | Y2: =IFERROR(VLOOKUP(M2,Tablas_Equivalencia!$G$3:$H$6,2,FALSE),"Sin dato") | Z2: =IF(J2<=24,"18-24","25-29") | AA2: =IF(M2<>1,"",IF(P2=2,1,0)) | AB2: =IF(M2<>1,"",IF(O2>=2,1,0)) | AC2: =IF(M2<>1,"",IF(OR(Q2=999,Q2=""),"",IF(OR(Q2<35,Q2>48),1,0))) | AD2: =IF(COUNT(AA2:AC2)<3,"",SUM(AA2:AC2)) | AE2: =IF(L2>=4,2,IF(L2>=2,1,0)) | AF2: =IF(L2>=5,1,0) | AG2: =AE2+AF2 | AH2: =IF(M2<>1,"",IF(OR(R2=-9,R2=""),"",R2)) | AI2: =IF(M2<>1,"",IF(OR(Q2=999,Q2=""),"",Q2))
A3: TQRMNOP100002 | B3: 2025 | C3: 1 | D3: 41 | E3: N | F3: 12 | G3: 1603 | H3: 3 | I3: 2 | J3: 18 | K3: 2 | L3: 1 | M3: 3 | R3: 0 | S3: 0 | T3: 0 | U3: 367200 | V3: =IFERROR(VLOOKUP(D3,Tablas_Equivalencia!$A$3:$B$8,2,FALSE),"Sin dato") | W3: =IFERROR(VLOOKUP(L3,Tablas_Equivalencia!$D$3:$E$9,2,FALSE),"Sin dato") | X3: =IF(I3=1,"Varón","Mujer") | Y3: =IFERROR(VLOOKUP(M3,Tablas_Equivalencia!$G$3:$H$6,2,FALSE),"Sin dato") | Z3: =IF(J3<=24,"18-24","25-29") | AA3: =IF(M3<>1,"",IF(P3=2,1,0)) | AB3: =IF(M3<>1,"",IF(O3>=2,1,0)) | AC3: =IF(M3<>1,"",IF(OR(Q3=999,Q3=""),"",IF(OR(Q3<35,Q3>48),1,0))) | AD3: =IF(COUNT(AA3:AC3)<3,"",SUM(AA3:AC3)) | AE3: =IF(L3>=4,2,IF(L3>=2,1,0)) | AF3: =IF(L3>=5,1,0) | AG3: =AE3+AF3 | AH3: =IF(M3<>1,"",IF(OR(R3=-9,R3=""),"",R3)) | AI3: =IF(M3<>1,"",IF(OR(Q3=999,Q3=""),"",Q3))
A4: TQRMNOP100005 | B4: 2025 | C4: 1 | D4: 43 | E4: N | F4: 34 | G4: 1073 | H4: 1 | I4: 2 | J4: 28 | K4: 1 | L4: 4 | M4: 1 | N4: 2 | O4: 2 | P4: 2 | Q4: 32 | R4: 271000 | S4: 0 | T4: 271000 | U4: 169600 | V4: =IFERROR(VLOOKUP(D4,Tablas_Equivalencia!$A$3:$B$8,2,FALSE),"Sin dato") | W4: =IFERROR(VLOOKUP(L4,Tablas_Equivalencia!$D$3:$E$9,2,FALSE),"Sin dato") | X4: =IF(I4=1,"Varón","Mujer") | Y4: =IFERROR(VLOOKUP(M4,Tablas_Equivalencia!$G$3:$H$6,2,FALSE),"Sin dato") | Z4: =IF(J4<=24,"18-24","25-29") | AA4: =IF(M4<>1,"",IF(P4=2,1,0)) | AB4: =IF(M4<>1,"",IF(O4>=2,1,0)) | AC4: =IF(M4<>1,"",IF(OR(Q4=999,Q4=""),"",IF(OR(Q4<35,Q4>48),1,0))) | AD4: =IF(COUNT(AA4:AC4)<3,"",SUM(AA4:AC4)) | AE4: =IF(L4>=4,2,IF(L4>=2,1,0)) | AF4: =IF(L4>=5,1,0) | AG4: =AE4+AF4 | AH4: =IF(M4<>1,"",IF(OR(R4=-9,R4=""),"",R4)) | AI4: =IF(M4<>1,"",IF(OR(Q4=999,Q4=""),"",Q4))
A5: TQRMNOP100010 | B5: 2025 | C5: 1 | D5: 44 | E5: N | F5: 93 | G5: 1288 | H5: 1 | I5: 2 | J5: 18 | K5: 2 | L5: 4 | M5: 3 | R5: 0 | S5: 0 | T5: 0 | U5: 161800 | V5: =IFERROR(VLOOKUP(D5,Tablas_Equivalencia!$A$3:$B$8,2,FALSE),"Sin dato") | W5: =IFERROR(VLOOKUP(L5,Tablas_Equivalencia!$D$3:$E$9,2,FALSE),"Sin dato") | X5: =IF(I5=1,"Varón","Mujer") | Y5: =IFERROR(VLOOKUP(M5,Tablas_Equivalencia!$G$3:$H$6,2,FALSE),"Sin dato") | Z5: =IF(J5<=24,"18-24","25-29") | AA5: =IF(M5<>1,"",IF(P5=2,1,0)) | AB5: =IF(M5<>1,"",IF(O5>=2,1,0)) | AC5: =IF(M5<>1,"",IF(OR(Q5=999,Q5=""),"",IF(OR(Q5<35,Q5>48),1,0))) | AD5: =IF(COUNT(AA5:AC5)<3,"",SUM(AA5:AC5)) | AE5: =IF(L5>=4,2,IF(L5>=2,1,0)) | AF5: =IF(L5>=5,1,0) | AG5: =AE5+AF5 | AH5: =IF(M5<>1,"",IF(OR(R5=-9,R5=""),"",R5)) | AI5: =IF(M5<>1,"",IF(OR(Q5=999,Q5=""),"",Q5))
A6: TQRMNOP100012 | B6: 2025 | C6: 1 | D6: 42 | E6: N | F6: 27 | G6: 1734 | H6: 3 | I6: 2 | J6: 23 | K6: 2 | L6: 5 | M6: 1 | N6: 3 | O6: 2 | P6: 2 | Q6: 27 | R6: 371000 | S6: 0 | T6: 371000 | U6: 85200 | V6: =IFERROR(VLOOKUP(D6,Tablas_Equivalencia!$A$3:$B$8,2,FALSE),"Sin dato") | W6: =IFERROR(VLOOKUP(L6,Tablas_Equivalencia!$D$3:$E$9,2,FALSE),"Sin dato") | X6: =IF(I6=1,"Varón","Mujer") | Y6: =IFERROR(VLOOKUP(M6,Tablas_Equivalencia!$G$3:$H$6,2,FALSE),"Sin dato") | Z6: =IF(J6<=24,"18-24","25-29") | AA6: =IF(M6<>1,"",IF(P6=2,1,0)) | AB6: =IF(M6<>1,"",IF(O6>=2,1,0)) | AC6: =IF(M6<>1,"",IF(OR(Q6=999,Q6=""),"",IF(OR(Q6<35,Q6>48),1,0))) | AD6: =IF(COUNT(AA6:AC6)<3,"",SUM(AA6:AC6)) | AE6: =IF(L6>=4,2,IF(L6>=2,1,0)) | AF6: =IF(L6>=5,1,0) | AG6: =AE6+AF6 | AH6: =IF(M6<>1,"",IF(OR(R6=-9,R6=""),"",R6)) | AI6: =IF(M6<>1,"",IF(OR(Q6=999,Q6=""),"",Q6))
A7: TQRMNOP100013 | B7: 2025 | C7: 1 | D7: 43 | E7: S | F7: 20 | G7: 667 | H7: 1 | I7: 2 | J7: 28 | K7: 2 | L7: 6 | M7: 1 | N7: 3 | O7: 1 | P7: 1 | Q7: 37 | R7: 620000 | S7: 0 | T7: 620000 | U7: 163300 | V7: =IFERROR(VLOOKUP(D7,Tablas_Equivalencia!$A$3:$B$8,2,FALSE),"Sin dato") | W7: =IFERROR(VLOOKUP(L7,Tablas_Equivalencia!$D$3:$E$9,2,FALSE),"Sin dato") | X7: =IF(I7=1,"Varón","Mujer") | Y7: =IFERROR(VLOOKUP(M7,Tablas_Equivalencia!$G$3:$H$6,2,FALSE),"Sin dato") | Z7: =IF(J7<=24,"18-24","25-29") | AA7: =IF(M7<>1,"",IF(P7=2,1,0)) | AB7: =IF(M7<>1,"",IF(O7>=2,1,0)) | AC7: =IF(M7<>1,"",IF(OR(Q7=999,Q7=""),"",IF(OR(Q7<35,Q7>48),1,0))) | AD7: =IF(COUNT(AA7:AC7)<3,"",SUM(AA7:AC7)) | AE7: =IF(L7>=4,2,IF(L7>=2,1,0)) | AF7: =IF(L7>=5,1,0) | AG7: =AE7+AF7 | AH7: =IF(M7<>1,"",IF(OR(R7=-9,R7=""),"",R7)) | AI7: =IF(M7<>1,"",IF(OR(Q7=999,Q7=""),"",Q7))
A8: TQRMNOP100014 | B8: 2025 | C8: 1 | D8: 41 | E8: N | F8: 12 | G8: 1462 | H8: 1 | I8: 2 | J8: 22 | K8: 2 | L8: 5 | M8: 3 | R8: 0 | S8: 30000 | T8: 30000 | U8: 158000 | V8: =IFERROR(VLOOKUP(D8,Tablas_Equivalencia!$A$3:$B$8,2,FALSE),"Sin dato") | W8: =IFERROR(VLOOKUP(L8,Tablas_Equivalencia!$D$3:$E$9,2,FALSE),"Sin dato") | X8: =IF(I8=1,"Varón","Mujer") | Y8: =IFERROR(VLOOKUP(M8,Tablas_Equivalencia!$G$3:$H$6,2,FALSE),"Sin dato") | Z8: =IF(J8<=24,"18-24","25-29") | AA8: =IF(M8<>1,"",IF(P8=2,1,0)) | AB8: =IF(M8<>1,"",IF(O8>=2,1,0)) | AC8: =IF(M8<>1,"",IF(OR(Q8=999,Q8=""),"",IF(OR(Q8<35,Q8>48),1,0))) | AD8: =IF(COUNT(AA8:AC8)<3,"",SUM(AA8:AC8)) | AE8: =IF(L8>=4,2,IF(L8>=2,1,0)) | AF8: =IF(L8>=5,1,0) | AG8: =AE8+AF8 | AH8: =IF(M8<>1,"",IF(OR(R8=-9,R8=""),"",R8)) | AI8: =IF(M8<>1,"",IF(OR(Q8=999,Q8=""),"",Q8))
A9: TQRMNOP100031 | B9: 2025 | C9: 1 | D9: 43 | E9: S | F9: 17 | G9: 925 | H9: 1 | I9: 1 | J9: 28 | K9: 2 | L9: 4 | M9: 1 | N9: 3 | O9: 1 | P9: 1 | Q9: 35 | R9: 390000 | S9: 0 | T9: 390000 | U9: 81800 | V9: =IFERROR(VLOOKUP(D9,Tablas_Equivalencia!$A$3:$B$8,2,FALSE),"Sin dato") | W9: =IFERROR(VLOOKUP(L9,Tablas_Equivalencia!$D$3:$E$9,2,FALSE),"Sin dato") | X9: =IF(I9=1,"Varón","Mujer") | Y9: =IFERROR(VLOOKUP(M9,Tablas_Equivalencia!$G$3:$H$6,2,FALSE),"Sin dato") | Z9: =IF(J9<=24,"18-24","25-29") | AA9: =IF(M9<>1,"",IF(P9=2,1,0)) | AB9: =IF(M9<>1,"",IF(O9>=2,1,0)) | AC9: =IF(M9<>1,"",IF(OR(Q9=999,Q9=""),"",IF(OR(Q9<35,Q9>48),1,0))) | AD9: =IF(COUNT(AA9:AC9)<3,"",SUM(AA9:AC9)) | AE9: =IF(L9>=4,2,IF(L9>=2,1,0)) | AF9: =IF(L9>=5,1,0) | AG9: =AE9+AF9 | AH9: =IF(M9<>1,"",IF(OR(R9=-9,R9=""),"",R9)) | AI9: =IF(M9<>1,"",IF(OR(Q9=999,Q9=""),"",Q9))
A10: TQRMNOP100034 | B10: 2025 | C10: 1 | D10: 40 | E10: S | F10: 7 | G10: 728 | H10: 3 | I10: 2 | J10: 25 | K10: 2 | L10: 6 | M10: 1 | N10: 3 | O10: 1 | P10: 1 | Q10: 35 | R10: 990000 | S10: 0 | T10: 990000 | U10: 37600 | V10: =IFERROR(VLOOKUP(D10,Tablas_Equivalencia!$A$3:$B$8,2,FALSE),"Sin dato") | W10: =IFERROR(VLOOKUP(L10,Tablas_Equivalencia!$D$3:$E$9,2,FALSE),"Sin dato") | X10: =IF(I10=1,"Varón","Mujer") | Y10: =IFERROR(VLOOKUP(M10,Tablas_Equivalencia!$G$3:$H$6,2,FALSE),"Sin dato") | Z10: =IF(J10<=24,"18-24","25-29") | AA10: =IF(M10<>1,"",IF(P10=2,1,0)) | AB10: =IF(M10<>1,"",IF(O10>=2,1,0)) | AC10: =IF(M10<>1,"",IF(OR(Q10=999,Q10=""),"",IF(OR(Q10<35,Q10>48),1,0))) | AD10: =IF(COUNT(AA10:AC10)<3,"",SUM(AA10:AC10)) | AE10: =IF(L10>=4,2,IF(L10>=2,1,0)) | AF10: =IF(L10>=5,1,0) | AG10: =AE10+AF10 | AH10: =IF(M10<>1,"",IF(OR(R10=-9,R10=""),"",R10)) | AI10: =IF(M10<>1,"",IF(OR(Q10=999,Q10=""),"",Q10))
A11: TQRMNOP100041 | B11: 2025 | C11: 1 | D11: 40 | E11: N | F11: 22 | G11: 1345 | H11: 1 | I11: 2 | J11: 24 | K11: 1 | L11: 4 | M11: 1 | N11: 3 | O11: 2 | P11: 2 | Q11: 41 | R11: -9 | S11: 0 | T11: 0 | U11: 187700 | V11: =IFERROR(VLOOKUP(D11,Tablas_Equivalencia!$A$3:$B$8,2,FALSE),"Sin dato") | W11: =IFERROR(VLOOKUP(L11,Tablas_Equivalencia!$D$3:$E$9,2,FALSE),"Sin dato") | X11: =IF(I11=1,"Varón","Mujer") | Y11: =IFERROR(VLOOKUP(M11,Tablas_Equivalencia!$G$3:$H$6,2,FALSE),"Sin dato") | Z11: =IF(J11<=24,"18-24","25-29") | AA11: =IF(M11<>1,"",IF(P11=2,1,0)) | AB11: =IF(M11<>1,"",IF(O11>=2,1,0)) | AC11: =IF(M11<>1,"",IF(OR(Q11=999,Q11=""),"",IF(OR(Q11<35,Q11>48),1,0))) | AD11: =IF(COUNT(AA11:AC11)<3,"",SUM(AA11:AC11)) | AE11: =IF(L11>=4,2,IF(L11>=2,1,0)) | AF11: =IF(L11>=5,1,0) | AG11: =AE11+AF11 | AH11: =IF(M11<>1,"",IF(OR(R11=-9,R11=""),"",R11)) | AI11: =IF(M11<>1,"",IF(OR(Q11=999,Q11=""),"",Q11))
A12: TQRMNOP100060 | B12: 2025 | C12: 1 | D12: 41 | E12: N | F12: 12 | G12: 445 | H12: 1 | I12: 1 | J12: 24 | K12: 2 | L12: 4 | M12: 3 | R12: 0 | S12: 0 | T12: 0 | U12: 179800 | V12: =IFERROR(VLOOKUP(D12,Tablas_Equivalencia!$A$3:$B$8,2,FALSE),"Sin dato") | W12: =IFERROR(VLOOKUP(L12,Tablas_Equivalencia!$D$3:$E$9,2,FALSE),"Sin dato") | X12: =IF(I12=1,"Varón","Mujer") | Y12: =IFERROR(VLOOKUP(M12,Tablas_Equivalencia!$G$3:$H$6,2,FALSE),"Sin dato") | Z12: =IF(J12<=24,"18-24","25-29") | AA12: =IF(M12<>1,"",IF(P12=2,1,0)) | AB12: =IF(M12<>1,"",IF(O12>=2,1,0)) | AC12: =IF(M12<>1,"",IF(OR(Q12=999,Q12=""),"",IF(OR(Q12<35,Q12>48),1,0))) | AD12: =IF(COUNT(AA12:AC12)<3,"",SUM(AA12:AC12)) | AE12: =IF(L12>=4,2,IF(L12>=2,1,0)) | AF12: =IF(L12>=5,1,0) | AG12: =AE12+AF12 | AH12: =IF(M12<>1,"",IF(OR(R12=-9,R12=""),"",R12)) | AI12: =IF(M12<>1,"",IF(OR(Q12=999,Q12=""),"",Q12))
A13: TQRMNOP100066 | B13: 2025 | C13: 1 | D13: 1 | E13: S | F13: 33 | G13: 586 | H13: 3 | I13: 2 | J13: 27 | K13: 1 | L13: 6 | M13: 3 | R13: 0 | S13: 0 | T13: 0 | U13: 89100 | V13: =IFERROR(VLOOKUP(D13,Tablas_Equivalencia!$A$3:$B$8,2,FALSE),"Sin dato") | W13: =IFERROR(VLOOKUP(L13,Tablas_Equivalencia!$D$3:$E$9,2,FALSE),"Sin dato") | X13: =IF(I13=1,"Varón","Mujer") | Y13: =IFERROR(VLOOKUP(M13,Tablas_Equivalencia!$G$3:$H$6,2,FALSE),"Sin dato") | Z13: =IF(J13<=24,"18-24","25-29") | AA13: =IF(M13<>1,"",IF(P13=2,1,0)) | AB13: =IF(M13<>1,"",IF(O13>=2,1,0)) | AC13: =IF(M13<>1,"",IF(OR(Q13=999,Q13=""),"",IF(OR(Q13<35,Q13>48),1,0))) | AD13: =IF(COUNT(AA13:AC13)<3,"",SUM(AA13:AC13)) | AE13: =IF(L13>=4,2,IF(L13>=2,1,0)) | AF13: =IF(L13>=5,1,0) | AG13: =AE13+AF13 | AH13: =IF(M13<>1,"",IF(OR(R13=-9,R13=""),"",R13)) | AI13: =IF(M13<>1,"",IF(OR(Q13=999,Q13=""),"",Q13))
A14: TQRMNOP100068 | B14: 2025 | C14: 1 | D14: 43 | E14: S | F14: 20 | G14: 418 | H14: 3 | I14: 2 | J14: 24 | K14: 1 | L14: 5 | M14: 1 | N14: 3 | O14: 2 | P14: 2 | Q14: 32 | R14: 475000 | S14: 54000 | T14: 529000 | U14: 42500 | V14: =IFERROR(VLOOKUP(D14,Tablas_Equivalencia!$A$3:$B$8,2,FALSE),"Sin dato") | W14: =IFERROR(VLOOKUP(L14,Tablas_Equivalencia!$D$3:$E$9,2,FALSE),"Sin dato") | X14: =IF(I14=1,"Varón","Mujer") | Y14: =IFERROR(VLOOKUP(M14,Tablas_Equivalencia!$G$3:$H$6,2,FALSE),"Sin dato") | Z14: =IF(J14<=24,"18-24","25-29") | AA14: =IF(M14<>1,"",IF(P14=2,1,0)) | AB14: =IF(M14<>1,"",IF(O14>=2,1,0)) | AC14: =IF(M14<>1,"",IF(OR(Q14=999,Q14=""),"",IF(OR(Q14<35,Q14>48),1,0))) | AD14: =IF(COUNT(AA14:AC14)<3,"",SUM(AA14:AC14)) | AE14: =IF(L14>=4,2,IF(L14>=2,1,0)) | AF14: =IF(L14>=5,1,0) | AG14: =AE14+AF14 | AH14: =IF(M14<>1,"",IF(OR(R14=-9,R14=""),"",R14)) | AI14: =IF(M14<>1,"",IF(OR(Q14=999,Q14=""),"",Q14))
A15: TQRMNOP100071 | B15: 2025 | C15: 1 | D15: 40 | E15: N | F15: 9 | G15: 971 | H15: 3 | I15: 1 | J15: 19 | K15: 1 | L15: 4 | M15: 3 | R15: 0 | S15: 0 | T15: 0 | U15: 115200 | V15: =IFERROR(VLOOKUP(D15,Tablas_Equivalencia!$A$3:$B$8,2,FALSE),"Sin dato") | W15: =IFERROR(VLOOKUP(L15,Tablas_Equivalencia!$D$3:$E$9,2,FALSE),"Sin dato") | X15: =IF(I15=1,"Varón","Mujer") | Y15: =IFERROR(VLOOKUP(M15,Tablas_Equivalencia!$G$3:$H$6,2,FALSE),"Sin dato") | Z15: =IF(J15<=24,"18-24","25-29") | AA15: =IF(M15<>1,"",IF(P15=2,1,0)) | AB15: =IF(M15<>1,"",IF(O15>=2,1,0)) | AC15: =IF(M15<>1,"",IF(OR(Q15=999,Q15=""),"",IF(OR(Q15<35,Q15>48),1,0))) | AD15: =IF(COUNT(AA15:AC15)<3,"",SUM(AA15:AC15)) | AE15: =IF(L15>=4,2,IF(L15>=2,1,0)) | AF15: =IF(L15>=5,1,0) | AG15: =AE15+AF15 | AH15: =IF(M15<>1,"",IF(OR(R15=-9,R15=""),"",R15)) | AI15: =IF(M15<>1,"",IF(OR(Q15=999,Q15=""),"",Q15))
A16: TQRMNOP100072 | B16: 2025 | C16: 1 | D16: 43 | E16: N | F16: 29 | G16: 738 | H16: 3 | I16: 1 | J16: 24 | K16: 1 | L16: 5 | M16: 2 | R16: 0 | S16: 0 | T16: 0 | U16: 267100 | V16: =IFERROR(VLOOKUP(D16,Tablas_Equivalencia!$A$3:$B$8,2,FALSE),"Sin dato") | W16: =IFERROR(VLOOKUP(L16,Tablas_Equivalencia!$D$3:$E$9,2,FALSE),"Sin dato") | X16: =IF(I16=1,"Varón","Mujer") | Y16: =IFERROR(VLOOKUP(M16,Tablas_Equivalencia!$G$3:$H$6,2,FALSE),"Sin dato") | Z16: =IF(J16<=24,"18-24","25-29") | AA16: =IF(M16<>1,"",IF(P16=2,1,0)) | AB16: =IF(M16<>1,"",IF(O16>=2,1,0)) | AC16: =IF(M16<>1,"",IF(OR(Q16=999,Q16=""),"",IF(OR(Q16<35,Q16>48),1,0))) | AD16: =IF(COUNT(AA16:AC16)<3,"",SUM(AA16:AC16)) | AE16: =IF(L16>=4,2,IF(L16>=2,1,0)) | AF16: =IF(L16>=5,1,0) | AG16: =AE16+AF16 | AH16: =IF(M16<>1,"",IF(OR(R16=-9,R16=""),"",R16)) | AI16: =IF(M16<>1,"",IF(OR(Q16=999,Q16=""),"",Q16))
A17: TQRMNOP100074 | B17: 2025 | C17: 1 | D17: 43 | E17: S | F17: 19 | G17: 1969 | H17: 1 | I17: 1 | J17: 23 | K17: 2 | L17: 6 | M17: 1 | N17: 3 | O17: 1 | P17: 1 | Q17: 53 | R17: 1804000 | S17: 0 | T17: 1804000 | U17: 134600 | V17: =IFERROR(VLOOKUP(D17,Tablas_Equivalencia!$A$3:$B$8,2,FALSE),"Sin dato") | W17: =IFERROR(VLOOKUP(L17,Tablas_Equivalencia!$D$3:$E$9,2,FALSE),"Sin dato") | X17: =IF(I17=1,"Varón","Mujer") | Y17: =IFERROR(VLOOKUP(M17,Tablas_Equivalencia!$G$3:$H$6,2,FALSE),"Sin dato") | Z17: =IF(J17<=24,"18-24","25-29") | AA17: =IF(M17<>1,"",IF(P17=2,1,0)) | AB17: =IF(M17<>1,"",IF(O17>=2,1,0)) | AC17: =IF(M17<>1,"",IF(OR(Q17=999,Q17=""),"",IF(OR(Q17<35,Q17>48),1,0))) | AD17: =IF(COUNT(AA17:AC17)<3,"",SUM(AA17:AC17)) | AE17: =IF(L17>=4,2,IF(L17>=2,1,0)) | AF17: =IF(L17>=5,1,0) | AG17: =AE17+AF17 | AH17: =IF(M17<>1,"",IF(OR(R17=-9,R17=""),"",R17)) | AI17: =IF(M17<>1,"",IF(OR(Q17=999,Q17=""),"",Q17))
A18: TQRMNOP100075 | B18: 2025 | C18: 1 | D18: 42 | E18: N | F18: 25 | G18: 1744 | H18: 3 | I18: 1 | J18: 27 | K18: 2 | L18: 3 | M18: 1 | N18: 3 | O18: 3 | P18: 2 | Q18: 37 | R18: 388000 | S18: 0 | T18: 388000 | U18: 191700 | V18: =IFERROR(VLOOKUP(D18,Tablas_Equivalencia!$A$3:$B$8,2,FALSE),"Sin dato") | W18: =IFERROR(VLOOKUP(L18,Tablas_Equivalencia!$D$3:$E$9,2,FALSE),"Sin dato") | X18: =IF(I18=1,"Varón","Mujer") | Y18: =IFERROR(VLOOKUP(M18,Tablas_Equivalencia!$G$3:$H$6,2,FALSE),"Sin dato") | Z18: =IF(J18<=24,"18-24","25-29") | AA18: =IF(M18<>1,"",IF(P18=2,1,0)) | AB18: =IF(M18<>1,"",IF(O18>=2,1,0)) | AC18: =IF(M18<>1,"",IF(OR(Q18=999,Q18=""),"",IF(OR(Q18<35,Q18>48),1,0))) | AD18: =IF(COUNT(AA18:AC18)<3,"",SUM(AA18:AC18)) | AE18: =IF(L18>=4,2,IF(L18>=2,1,0)) | AF18: =IF(L18>=5,1,0) | AG18: =AE18+AF18 | AH18: =IF(M18<>1,"",IF(OR(R18=-9,R18=""),"",R18)) | AI18: =IF(M18<>1,"",IF(OR(Q18=999,Q18=""),"",Q18))
A19: TQRMNOP100080 | B19: 2025 | C19: 1 | D19: 1 | E19: S | F19: 33 | G19: 1334 | H19: 3 | I19: 2 | J19: 18 | K19: 1 | L19: 4 | M19: 3 | R19: 0 | S19: 0 | T19: 0 | U19: 200400 | V19: =IFERROR(VLOOKUP(D19,Tablas_Equivalencia!$A$3:$B$8,2,FALSE),"Sin dato") | W19: =IFERROR(VLOOKUP(L19,Tablas_Equivalencia!$D$3:$E$9,2,FALSE),"Sin dato") | X19: =IF(I19=1,"Varón","Mujer") | Y19: =IFERROR(VLOOKUP(M19,Tablas_Equivalencia!$G$3:$H$6,2,FALSE),"Sin dato") | Z19: =IF(J19<=24,"18-24","25-29") | AA19: =IF(M19<>1,"",IF(P19=2,1,0)) | AB19: =IF(M19<>1,"",IF(O19>=2,1,0)) | AC19: =IF(M19<>1,"",IF(OR(Q19=999,Q19=""),"",IF(OR(Q19<35,Q19>48),1,0))) | AD19: =IF(COUNT(AA19:AC19)<3,"",SUM(AA19:AC19)) | AE19: =IF(L19>=4,2,IF(L19>=2,1,0)) | AF19: =IF(L19>=5,1,0) | AG19: =AE19+AF19 | AH19: =IF(M19<>1,"",IF(OR(R19=-9,R19=""),"",R19)) | AI19: =IF(M19<>1,"",IF(OR(Q19=999,Q19=""),"",Q19))
A20: TQRMNOP100095 | B20: 2025 | C20: 1 | D20: 42 | E20: N | F20: 25 | G20: 1444 | H20: 1 | I20: 2 | J20: 25 | K20: 2 | L20: 5 | M20: 1 | N20: 2 | O20: 2 | P20: 2 | Q20: 34 | R20: 682000 | S20: 0 | T20: 682000 | U20: 77300 | V20: =IFERROR(VLOOKUP(D20,Tablas_Equivalencia!$A$3:$B$8,2,FALSE),"Sin dato") | W20: =IFERROR(VLOOKUP(L20,Tablas_Equivalencia!$D$3:$E$9,2,FALSE),"Sin dato") | X20: =IF(I20=1,"Varón","Mujer") | Y20: =IFERROR(VLOOKUP(M20,Tablas_Equivalencia!$G$3:$H$6,2,FALSE),"Sin dato") | Z20: =IF(J20<=24,"18-24","25-29") | AA20: =IF(M20<>1,"",IF(P20=2,1,0)) | AB20: =IF(M20<>1,"",IF(O20>=2,1,0)) | AC20: =IF(M20<>1,"",IF(OR(Q20=999,Q20=""),"",IF(OR(Q20<35,Q20>48),1,0))) | AD20: =IF(COUNT(AA20:AC20)<3,"",SUM(AA20:AC20)) | AE20: =IF(L20>=4,2,IF(L20>=2,1,0)) | AF20: =IF(L20>=5,1,0) | AG20: =AE20+AF20 | AH20: =IF(M20<>1,"",IF(OR(R20=-9,R20=""),"",R20)) | AI20: =IF(M20<>1,"",IF(OR(Q20=999,Q20=""),"",Q20))
A21: TQRMNOP100097 | B21: 2025 | C21: 1 | D21: 43 | E21: S | F21: 19 | G21: 1024 | H21: 3 | I21: 2 | J21: 19 | K21: 1 | L21: 5 | M21: 3 | R21: 0 | S21: 0 | T21: 0 | U21: 75100 | V21: =IFERROR(VLOOKUP(D21,Tablas_Equivalencia!$A$3:$B$8,2,FALSE),"Sin dato") | W21: =IFERROR(VLOOKUP(L21,Tablas_Equivalencia!$D$3:$E$9,2,FALSE),"Sin dato") | X21: =IF(I21=1,"Varón","Mujer") | Y21: =IFERROR(VLOOKUP(M21,Tablas_Equivalencia!$G$3:$H$6,2,FALSE),"Sin dato") | Z21: =IF(J21<=24,"18-24","25-29") | AA21: =IF(M21<>1,"",IF(P21=2,1,0)) | AB21: =IF(M21<>1,"",IF(O21>=2,1,0)) | AC21: =IF(M21<>1,"",IF(OR(Q21=999,Q21=""),"",IF(OR(Q21<35,Q21>48),1,0))) | AD21: =IF(COUNT(AA21:AC21)<3,"",SUM(AA21:AC21)) | AE21: =IF(L21>=4,2,IF(L21>=2,1,0)) | AF21: =IF(L21>=5,1,0) | AG21: =AE21+AF21 | AH21: =IF(M21<>1,"",IF(OR(R21=-9,R21=""),"",R21)) | AI21: =IF(M21<>1,"",IF(OR(Q21=999,Q21=""),"",Q21))
A22: TQRMNOP100117 | B22: 2025 | C22: 1 | D22: 41 | E22: S | F22: 8 | G22: 1977 | H22: 3 | I22: 2 | J22: 20 | K22: 2 | L22: 3 | M22: 3 | R22: 0 | S22: 69000 | T22: 69000 | U22: 118200 | V22: =IFERROR(VLOOKUP(D22,Tablas_Equivalencia!$A$3:$B$8,2,FALSE),"Sin dato") | W22: =IFERROR(VLOOKUP(L22,Tablas_Equivalencia!$D$3:$E$9,2,FALSE),"Sin dato") | X22: =IF(I22=1,"Varón","Mujer") | Y22: =IFERROR(VLOOKUP(M22,Tablas_Equivalencia!$G$3:$H$6,2,FALSE),"Sin dato") | Z22: =IF(J22<=24,"18-24","25-29") | AA22: =IF(M22<>1,"",IF(P22=2,1,0)) | AB22: =IF(M22<>1,"",IF(O22>=2,1,0)) | AC22: =IF(M22<>1,"",IF(OR(Q22=999,Q22=""),"",IF(OR(Q22<35,Q22>48),1,0))) | AD22: =IF(COUNT(AA22:AC22)<3,"",SUM(AA22:AC22)) | AE22: =IF(L22>=4,2,IF(L22>=2,1,0)) | AF22: =IF(L22>=5,1,0) | AG22: =AE22+AF22 | AH22: =IF(M22<>1,"",IF(OR(R22=-9,R22=""),"",R22)) | AI22: =IF(M22<>1,"",IF(OR(Q22=999,Q22=""),"",Q22))
A23: TQRMNOP100126 | B23: 2025 | C23: 1 | D23: 42 | E23: N | F23: 25 | G23: 604 | H23: 3 | I23: 1 | J23: 29 | K23: 1 | L23: 2 | M23: 1 | N23: 3 | O23: 3 | P23: 2 | Q23: 41 | R23: 418000 | S23: 0 | T23: 418000 | U23: 195000 | V23: =IFERROR(VLOOKUP(D23,Tablas_Equivalencia!$A$3:$B$8,2,FALSE),"Sin dato") | W23: =IFERROR(VLOOKUP(L23,Tablas_Equivalencia!$D$3:$E$9,2,FALSE),"Sin dato") | X23: =IF(I23=1,"Varón","Mujer") | Y23: =IFERROR(VLOOKUP(M23,Tablas_Equivalencia!$G$3:$H$6,2,FALSE),"Sin dato") | Z23: =IF(J23<=24,"18-24","25-29") | AA23: =IF(M23<>1,"",IF(P23=2,1,0)) | AB23: =IF(M23<>1,"",IF(O23>=2,1,0)) | AC23: =IF(M23<>1,"",IF(OR(Q23=999,Q23=""),"",IF(OR(Q23<35,Q23>48),1,0))) | AD23: =IF(COUNT(AA23:AC23)<3,"",SUM(AA23:AC23)) | AE23: =IF(L23>=4,2,IF(L23>=2,1,0)) | AF23: =IF(L23>=5,1,0) | AG23: =AE23+AF23 | AH23: =IF(M23<>1,"",IF(OR(R23=-9,R23=""),"",R23)) | AI23: =IF(M23<>1,"",IF(OR(Q23=999,Q23=""),"",Q23))
A24: TQRMNOP100129 | B24: 2025 | C24: 1 | D24: 41 | E24: N | F24: 15 | G24: 1702 | H24: 3 | I24: 2 | J24: 27 | K24: 2 | L24: 2 | M24: 3 | R24: 0 | S24: 0 | T24: 0 | U24: 171700 | V24: =IFERROR(VLOOKUP(D24,Tablas_Equivalencia!$A$3:$B$8,2,FALSE),"Sin dato") | W24: =IFERROR(VLOOKUP(L24,Tablas_Equivalencia!$D$3:$E$9,2,FALSE),"Sin dato") | X24: =IF(I24=1,"Varón","Mujer") | Y24: =IFERROR(VLOOKUP(M24,Tablas_Equivalencia!$G$3:$H$6,2,FALSE),"Sin dato") | Z24: =IF(J24<=24,"18-24","25-29") | AA24: =IF(M24<>1,"",IF(P24=2,1,0)) | AB24: =IF(M24<>1,"",IF(O24>=2,1,0)) | AC24: =IF(M24<>1,"",IF(OR(Q24=999,Q24=""),"",IF(OR(Q24<35,Q24>48),1,0))) | AD24: =IF(COUNT(AA24:AC24)<3,"",SUM(AA24:AC24)) | AE24: =IF(L24>=4,2,IF(L24>=2,1,0)) | AF24: =IF(L24>=5,1,0) | AG24: =AE24+AF24 | AH24: =IF(M24<>1,"",IF(OR(R24=-9,R24=""),"",R24)) | AI24: =IF(M24<>1,"",IF(OR(Q24=999,Q24=""),"",Q24))
A25: TQRMNOP100136 | B25: 2025 | C25: 1 | D25: 43 | E25: S | F25: 30 | G25: 1034 | H25: 3 | I25: 1 | J25: 24 | K25: 2 | L25: 6 | M25: 1 | N25: 1 | O25: 1 | P25: 1 | Q25: 22 | R25: 1107000 | S25: 0 | T25: 1107000 | U25: 174100 | V25: =IFERROR(VLOOKUP(D25,Tablas_Equivalencia!$A$3:$B$8,2,FALSE),"Sin dato") | W25: =IFERROR(VLOOKUP(L25,Tablas_Equivalencia!$D$3:$E$9,2,FALSE),"Sin dato") | X25: =IF(I25=1,"Varón","Mujer") | Y25: =IFERROR(VLOOKUP(M25,Tablas_Equivalencia!$G$3:$H$6,2,FALSE),"Sin dato") | Z25: =IF(J25<=24,"18-24","25-29") | AA25: =IF(M25<>1,"",IF(P25=2,1,0)) | AB25: =IF(M25<>1,"",IF(O25>=2,1,0)) | AC25: =IF(M25<>1,"",IF(OR(Q25=999,Q25=""),"",IF(OR(Q25<35,Q25>48),1,0))) | AD25: =IF(COUNT(AA25:AC25)<3,"",SUM(AA25:AC25)) | AE25: =IF(L25>=4,2,IF(L25>=2,1,0)) | AF25: =IF(L25>=5,1,0) | AG25: =AE25+AF25 | AH25: =IF(M25<>1,"",IF(OR(R25=-9,R25=""),"",R25)) | AI25: =IF(M25<>1,"",IF(OR(Q25=999,Q25=""),"",Q25))
A26: TQRMNOP100150 | B26: 2025 | C26: 1 | D26: 43 | E26: N | F26: 38 | G26: 735 | H26: 3 | I26: 2 | J26: 23 | K26: 1 | L26: 6 | M26: 3 | R26: 0 | S26: 0 | T26: 0 | U26: 92700 | V26: =IFERROR(VLOOKUP(D26,Tablas_Equivalencia!$A$3:$B$8,2,FALSE),"Sin dato") | W26: =IFERROR(VLOOKUP(L26,Tablas_Equivalencia!$D$3:$E$9,2,FALSE),"Sin dato") | X26: =IF(I26=1,"Varón","Mujer") | Y26: =IFERROR(VLOOKUP(M26,Tablas_Equivalencia!$G$3:$H$6,2,FALSE),"Sin dato") | Z26: =IF(J26<=24,"18-24","25-29") | AA26: =IF(M26<>1,"",IF(P26=2,1,0)) | AB26: =IF(M26<>1,"",IF(O26>=2,1,0)) | AC26: =IF(M26<>1,"",IF(OR(Q26=999,Q26=""),"",IF(OR(Q26<35,Q26>48),1,0))) | AD26: =IF(COUNT(AA26:AC26)<3,"",SUM(AA26:AC26)) | AE26: =IF(L26>=4,2,IF(L26>=2,1,0)) | AF26: =IF(L26>=5,1,0) | AG26: =AE26+AF26 | AH26: =IF(M26<>1,"",IF(OR(R26=-9,R26=""),"",R26)) | AI26: =IF(M26<>1,"",IF(OR(Q26=999,Q26=""),"",Q26))
A27: TQRMNOP100151 | B27: 2025 | C27: 1 | D27: 40 | E27: S | F27: 7 | G27: 519 | H27: 3 | I27: 2 | J27: 22 | K27: 2 | L27: 4 | M27: 1 | N27: 3 | O27: 2 | P27: 2 | Q27: 47 | R27: 166000 | S27: 0 | T27: 166000 | U27: 314000 | V27: =IFERROR(VLOOKUP(D27,Tablas_Equivalencia!$A$3:$B$8,2,FALSE),"Sin dato") | W27: =IFERROR(VLOOKUP(L27,Tablas_Equivalencia!$D$3:$E$9,2,FALSE),"Sin dato") | X27: =IF(I27=1,"Varón","Mujer") | Y27: =IFERROR(VLOOKUP(M27,Tablas_Equivalencia!$G$3:$H$6,2,FALSE),"Sin dato") | Z27: =IF(J27<=24,"18-24","25-29") | AA27: =IF(M27<>1,"",IF(P27=2,1,0)) | AB27: =IF(M27<>1,"",IF(O27>=2,1,0)) | AC27: =IF(M27<>1,"",IF(OR(Q27=999,Q27=""),"",IF(OR(Q27<35,Q27>48),1,0))) | AD27: =IF(COUNT(AA27:AC27)<3,"",SUM(AA27:AC27)) | AE27: =IF(L27>=4,2,IF(L27>=2,1,0)) | AF27: =IF(L27>=5,1,0) | AG27: =AE27+AF27 | AH27: =IF(M27<>1,"",IF(OR(R27=-9,R27=""),"",R27)) | AI27: =IF(M27<>1,"",IF(OR(Q27=999,Q27=""),"",Q27))
A28: TQRMNOP100153 | B28: 2025 | C28: 1 | D28: 1 | E28: S | F28: 33 | G28: 1430 | H28: 1 | I28: 2 | J28: 23 | K28: 2 | L28: 4 | M28: 1 | N28: 3 | O28: 1 | P28: 1 | Q28: 23 | R28: -9 | S28: 0 | T28: 0 | U28: 180300 | V28: =IFERROR(VLOOKUP(D28,Tablas_Equivalencia!$A$3:$B$8,2,FALSE),"Sin dato") | W28: =IFERROR(VLOOKUP(L28,Tablas_Equivalencia!$D$3:$E$9,2,FALSE),"Sin dato") | X28: =IF(I28=1,"Varón","Mujer") | Y28: =IFERROR(VLOOKUP(M28,Tablas_Equivalencia!$G$3:$H$6,2,FALSE),"Sin dato") | Z28: =IF(J28<=24,"18-24","25-29") | AA28: =IF(M28<>1,"",IF(P28=2,1,0)) | AB28: =IF(M28<>1,"",IF(O28>=2,1,0)) | AC28: =IF(M28<>1,"",IF(OR(Q28=999,Q28=""),"",IF(OR(Q28<35,Q28>48),1,0))) | AD28: =IF(COUNT(AA28:AC28)<3,"",SUM(AA28:AC28)) | AE28: =IF(L28>=4,2,IF(L28>=2,1,0)) | AF28: =IF(L28>=5,1,0) | AG28: =AE28+AF28 | AH28: =IF(M28<>1,"",IF(OR(R28=-9,R28=""),"",R28)) | AI28: =IF(M28<>1,"",IF(OR(Q28=999,Q28=""),"",Q28))
A29: TQRMNOP100155 | B29: 2025 | C29: 1 | D29: 1 | E29: S | F29: 33 | G29: 1001 | H29: 2 | I29: 2 | J29: 22 | K29: 1 | L29: 3 | M29: 1 | N29: 3 | O29: 1 | P29: 1 | Q29: 24 | R29: 615000 | S29: 0 | T29: 615000 | U29: 114100 | V29: =IFERROR(VLOOKUP(D29,Tablas_Equivalencia!$A$3:$B$8,2,FALSE),"Sin dato") | W29: =IFERROR(VLOOKUP(L29,Tablas_Equivalencia!$D$3:$E$9,2,FALSE),"Sin dato") | X29: =IF(I29=1,"Varón","Mujer") | Y29: =IFERROR(VLOOKUP(M29,Tablas_Equivalencia!$G$3:$H$6,2,FALSE),"Sin dato") | Z29: =IF(J29<=24,"18-24","25-29") | AA29: =IF(M29<>1,"",IF(P29=2,1,0)) | AB29: =IF(M29<>1,"",IF(O29>=2,1,0)) | AC29: =IF(M29<>1,"",IF(OR(Q29=999,Q29=""),"",IF(OR(Q29<35,Q29>48),1,0))) | AD29: =IF(COUNT(AA29:AC29)<3,"",SUM(AA29:AC29)) | AE29: =IF(L29>=4,2,IF(L29>=2,1,0)) | AF29: =IF(L29>=5,1,0) | AG29: =AE29+AF29 | AH29: =IF(M29<>1,"",IF(OR(R29=-9,R29=""),"",R29)) | AI29: =IF(M29<>1,"",IF(OR(Q29=999,Q29=""),"",Q29))
A30: TQRMNOP100157 | B30: 2025 | C30: 1 | D30: 40 | E30: N | F30: 23 | G30: 713 | H30: 3 | I30: 2 | J30: 19 | K30: 2 | L30: 4 | M30: 3 | R30: 0 | S30: 0 | T30: 0 | U30: 21100 | V30: =IFERROR(VLOOKUP(D30,Tablas_Equivalencia!$A$3:$B$8,2,FALSE),"Sin dato") | W30: =IFERROR(VLOOKUP(L30,Tablas_Equivalencia!$D$3:$E$9,2,FALSE),"Sin dato") | X30: =IF(I30=1,"Varón","Mujer") | Y30: =IFERROR(VLOOKUP(M30,Tablas_Equivalencia!$G$3:$H$6,2,FALSE),"Sin dato") | Z30: =IF(J30<=24,"18-24","25-29") | AA30: =IF(M30<>1,"",IF(P30=2,1,0)) | AB30: =IF(M30<>1,"",IF(O30>=2,1,0)) | AC30: =IF(M30<>1,"",IF(OR(Q30=999,Q30=""),"",IF(OR(Q30<35,Q30>48),1,0))) | AD30: =IF(COUNT(AA30:AC30)<3,"",SUM(AA30:AC30)) | AE30: =IF(L30>=4,2,IF(L30>=2,1,0)) | AF30: =IF(L30>=5,1,0) | AG30: =AE30+AF30 | AH30: =IF(M30<>1,"",IF(OR(R30=-9,R30=""),"",R30)) | AI30: =IF(M30<>1,"",IF(OR(Q30=999,Q30=""),"",Q30))
A31: TQRMNOP100158 | B31: 2025 | C31: 1 | D31: 1 | E31: S | F31: 33 | G31: 1597 | H31: 3 | I31: 2 | J31: 22 | K31: 1 | L31: 5 | M31: 3 | R31: 0 | S31: 0 | T31: 0 | U31: 99200 | V31: =IFERROR(VLOOKUP(D31,Tablas_Equivalencia!$A$3:$B$8,2,FALSE),"Sin dato") | W31: =IFERROR(VLOOKUP(L31,Tablas_Equivalencia!$D$3:$E$9,2,FALSE),"Sin dato") | X31: =IF(I31=1,"Varón","Mujer") | Y31: =IFERROR(VLOOKUP(M31,Tablas_Equivalencia!$G$3:$H$6,2,FALSE),"Sin dato") | Z31: =IF(J31<=24,"18-24","25-29") | AA31: =IF(M31<>1,"",IF(P31=2,1,0)) | AB31: =IF(M31<>1,"",IF(O31>=2,1,0)) | AC31: =IF(M31<>1,"",IF(OR(Q31=999,Q31=""),"",IF(OR(Q31<35,Q31>48),1,0))) | AD31: =IF(COUNT(AA31:AC31)<3,"",SUM(AA31:AC31)) | AE31: =IF(L31>=4,2,IF(L31>=2,1,0)) | AF31: =IF(L31>=5,1,0) | AG31: =AE31+AF31 | AH31: =IF(M31<>1,"",IF(OR(R31=-9,R31=""),"",R31)) | AI31: =IF(M31<>1,"",IF(OR(Q31=999,Q31=""),"",Q31))
A32: TQRMNOP100159 | B32: 2025 | C32: 1 | D32: 43 | E32: S | F32: 19 | G32: 615 | H32: 1 | I32: 1 | J32: 23 | K32: 2 | L32: 6 | M32: 1 | N32: 3 | O32: 2 | P32: 2 | Q32: 39 | R32: 880000 | S32: 0 | T32: 880000 | U32: 106200 | V32: =IFERROR(VLOOKUP(D32,Tablas_Equivalencia!$A$3:$B$8,2,FALSE),"Sin dato") | W32: =IFERROR(VLOOKUP(L32,Tablas_Equivalencia!$D$3:$E$9,2,FALSE),"Sin dato") | X32: =IF(I32=1,"Varón","Mujer") | Y32: =IFERROR(VLOOKUP(M32,Tablas_Equivalencia!$G$3:$H$6,2,FALSE),"Sin dato") | Z32: =IF(J32<=24,"18-24","25-29") | AA32: =IF(M32<>1,"",IF(P32=2,1,0)) | AB32: =IF(M32<>1,"",IF(O32>=2,1,0)) | AC32: =IF(M32<>1,"",IF(OR(Q32=999,Q32=""),"",IF(OR(Q32<35,Q32>48),1,0))) | AD32: =IF(COUNT(AA32:AC32)<3,"",SUM(AA32:AC32)) | AE32: =IF(L32>=4,2,IF(L32>=2,1,0)) | AF32: =IF(L32>=5,1,0) | AG32: =AE32+AF32 | AH32: =IF(M32<>1,"",IF(OR(R32=-9,R32=""),"",R32)) | AI32: =IF(M32<>1,"",IF(OR(Q32=999,Q32=""),"",Q32))
A33: TQRMNOP100165 | B33: 2025 | C33: 1 | D33: 1 | E33: S | F33: 32 | G33: 2127 | H33: 3 | I33: 2 | J33: 21 | K33: 1 | L33: 4 | M33: 1 | N33: 2 | O33: 2 | P33: 2 | Q33: 11 | R33: 177000 | S33: 63000 | T33: 240000 | U33: 132300 | V33: =IFERROR(VLOOKUP(D33,Tablas_Equivalencia!$A$3:$B$8,2,FALSE),"Sin dato") | W33: =IFERROR(VLOOKUP(L33,Tablas_Equivalencia!$D$3:$E$9,2,FALSE),"Sin dato") | X33: =IF(I33=1,"Varón","Mujer") | Y33: =IFERROR(VLOOKUP(M33,Tablas_Equivalencia!$G$3:$H$6,2,FALSE),"Sin dato") | Z33: =IF(J33<=24,"18-24","25-29") | AA33: =IF(M33<>1,"",IF(P33=2,1,0)) | AB33: =IF(M33<>1,"",IF(O33>=2,1,0)) | AC33: =IF(M33<>1,"",IF(OR(Q33=999,Q33=""),"",IF(OR(Q33<35,Q33>48),1,0))) | AD33: =IF(COUNT(AA33:AC33)<3,"",SUM(AA33:AC33)) | AE33: =IF(L33>=4,2,IF(L33>=2,1,0)) | AF33: =IF(L33>=5,1,0) | AG33: =AE33+AF33 | AH33: =IF(M33<>1,"",IF(OR(R33=-9,R33=""),"",R33)) | AI33: =IF(M33<>1,"",IF(OR(Q33=999,Q33=""),"",Q33))
A34: TQRMNOP100169 | B34: 2025 | C34: 1 | D34: 41 | E34: S | F34: 8 | G34: 1124 | H34: 3 | I34: 2 | J34: 28 | K34: 1 | L34: 5 | M34: 1 | N34: 1 | O34: 1 | P34: 1 | Q34: 28 | R34: -9 | S34: 0 | T34: 0 | U34: 192700 | V34: =IFERROR(VLOOKUP(D34,Tablas_Equivalencia!$A$3:$B$8,2,FALSE),"Sin dato") | W34: =IFERROR(VLOOKUP(L34,Tablas_Equivalencia!$D$3:$E$9,2,FALSE),"Sin dato") | X34: =IF(I34=1,"Varón","Mujer") | Y34: =IFERROR(VLOOKUP(M34,Tablas_Equivalencia!$G$3:$H$6,2,FALSE),"Sin dato") | Z34: =IF(J34<=24,"18-24","25-29") | AA34: =IF(M34<>1,"",IF(P34=2,1,0)) | AB34: =IF(M34<>1,"",IF(O34>=2,1,0)) | AC34: =IF(M34<>1,"",IF(OR(Q34=999,Q34=""),"",IF(OR(Q34<35,Q34>48),1,0))) | AD34: =IF(COUNT(AA34:AC34)<3,"",SUM(AA34:AC34)) | AE34: =IF(L34>=4,2,IF(L34>=2,1,0)) | AF34: =IF(L34>=5,1,0) | AG34: =AE34+AF34 | AH34: =IF(M34<>1,"",IF(OR(R34=-9,R34=""),"",R34)) | AI34: =IF(M34<>1,"",IF(OR(Q34=999,Q34=""),"",Q34))
A35: TQRMNOP100171 | B35: 2025 | C35: 1 | D35: 40 | E35: N | F35: 9 | G35: 672 | H35: 3 | I35: 2 | J35: 29 | K35: 1 | L35: 5 | M35: 3 | R35: 0 | S35: 0 | T35: 0 | U35: 236100 | V35: =IFERROR(VLOOKUP(D35,Tablas_Equivalencia!$A$3:$B$8,2,FALSE),"Sin dato") | W35: =IFERROR(VLOOKUP(L35,Tablas_Equivalencia!$D$3:$E$9,2,FALSE),"Sin dato") | X35: =IF(I35=1,"Varón","Mujer") | Y35: =IFERROR(VLOOKUP(M35,Tablas_Equivalencia!$G$3:$H$6,2,FALSE),"Sin dato") | Z35: =IF(J35<=24,"18-24","25-29") | AA35: =IF(M35<>1,"",IF(P35=2,1,0)) | AB35: =IF(M35<>1,"",IF(O35>=2,1,0)) | AC35: =IF(M35<>1,"",IF(OR(Q35=999,Q35=""),"",IF(OR(Q35<35,Q35>48),1,0))) | AD35: =IF(COUNT(AA35:AC35)<3,"",SUM(AA35:AC35)) | AE35: =IF(L35>=4,2,IF(L35>=2,1,0)) | AF35: =IF(L35>=5,1,0) | AG35: =AE35+AF35 | AH35: =IF(M35<>1,"",IF(OR(R35=-9,R35=""),"",R35)) | AI35: =IF(M35<>1,"",IF(OR(Q35=999,Q35=""),"",Q35))
A36: TQRMNOP100180 | B36: 2025 | C36: 1 | D36: 43 | E36: N | F36: 38 | G36: 1114 | H36: 1 | I36: 1 | J36: 21 | K36: 1 | L36: 3 | M36: 3 | R36: 0 | S36: 0 | T36: 0 | U36: 109800 | V36: =IFERROR(VLOOKUP(D36,Tablas_Equivalencia!$A$3:$B$8,2,FALSE),"Sin dato") | W36: =IFERROR(VLOOKUP(L36,Tablas_Equivalencia!$D$3:$E$9,2,FALSE),"Sin dato") | X36: =IF(I36=1,"Varón","Mujer") | Y36: =IFERROR(VLOOKUP(M36,Tablas_Equivalencia!$G$3:$H$6,2,FALSE),"Sin dato") | Z36: =IF(J36<=24,"18-24","25-29") | AA36: =IF(M36<>1,"",IF(P36=2,1,0)) | AB36: =IF(M36<>1,"",IF(O36>=2,1,0)) | AC36: =IF(M36<>1,"",IF(OR(Q36=999,Q36=""),"",IF(OR(Q36<35,Q36>48),1,0))) | AD36: =IF(COUNT(AA36:AC36)<3,"",SUM(AA36:AC36)) | AE36: =IF(L36>=4,2,IF(L36>=2,1,0)) | AF36: =IF(L36>=5,1,0) | AG36: =AE36+AF36 | AH36: =IF(M36<>1,"",IF(OR(R36=-9,R36=""),"",R36)) | AI36: =IF(M36<>1,"",IF(OR(Q36=999,Q36=""),"",Q36))
A37: TQRMNOP100183 | B37: 2025 | C37: 1 | D37: 44 | E37: N | F37: 2 | G37: 386 | H37: 1 | I37: 1 | J37: 23 | K37: 1 | L37: 3 | M37: 1 | N37: 2 | O37: 2 | P37: 2 | Q37: 33 | R37: 362000 | S37: 0 | T37: 362000 | U37: 321200 | V37: =IFERROR(VLOOKUP(D37,Tablas_Equivalencia!$A$3:$B$8,2,FALSE),"Sin dato") | W37: =IFERROR(VLOOKUP(L37,Tablas_Equivalencia!$D$3:$E$9,2,FALSE),"Sin dato") | X37: =IF(I37=1,"Varón","Mujer") | Y37: =IFERROR(VLOOKUP(M37,Tablas_Equivalencia!$G$3:$H$6,2,FALSE),"Sin dato") | Z37: =IF(J37<=24,"18-24","25-29") | AA37: =IF(M37<>1,"",IF(P37=2,1,0)) | AB37: =IF(M37<>1,"",IF(O37>=2,1,0)) | AC37: =IF(M37<>1,"",IF(OR(Q37=999,Q37=""),"",IF(OR(Q37<35,Q37>48),1,0))) | AD37: =IF(COUNT(AA37:AC37)<3,"",SUM(AA37:AC37)) | AE37: =IF(L37>=4,2,IF(L37>=2,1,0)) | AF37: =IF(L37>=5,1,0) | AG37: =AE37+AF37 | AH37: =IF(M37<>1,"",IF(OR(R37=-9,R37=""),"",R37)) | AI37: =IF(M37<>1,"",IF(OR(Q37=999,Q37=""),"",Q37))
A38: TQRMNOP100188 | B38: 2025 | C38: 1 | D38: 42 | E38: N | F38: 25 | G38: 1392 | H38: 3 | I38: 2 | J38: 23 | K38: 2 | L38: 6 | M38: 3 | R38: 0 | S38: 0 | T38: 0 | U38: 204600 | V38: =IFERROR(VLOOKUP(D38,Tablas_Equivalencia!$A$3:$B$8,2,FALSE),"Sin dato") | W38: =IFERROR(VLOOKUP(L38,Tablas_Equivalencia!$D$3:$E$9,2,FALSE),"Sin dato") | X38: =IF(I38=1,"Varón","Mujer") | Y38: =IFERROR(VLOOKUP(M38,Tablas_Equivalencia!$G$3:$H$6,2,FALSE),"Sin dato") | Z38: =IF(J38<=24,"18-24","25-29") | AA38: =IF(M38<>1,"",IF(P38=2,1,0)) | AB38: =IF(M38<>1,"",IF(O38>=2,1,0)) | AC38: =IF(M38<>1,"",IF(OR(Q38=999,Q38=""),"",IF(OR(Q38<35,Q38>48),1,0))) | AD38: =IF(COUNT(AA38:AC38)<3,"",SUM(AA38:AC38)) | AE38: =IF(L38>=4,2,IF(L38>=2,1,0)) | AF38: =IF(L38>=5,1,0) | AG38: =AE38+AF38 | AH38: =IF(M38<>1,"",IF(OR(R38=-9,R38=""),"",R38)) | AI38: =IF(M38<>1,"",IF(OR(Q38=999,Q38=""),"",Q38))
A39: TQRMNOP100189 | B39: 2025 | C39: 1 | D39: 40 | E39: S | F39: 7 | G39: 1839 | H39: 1 | I39: 1 | J39: 18 | K39: 1 | L39: 5 | M39: 1 | N39: 2 | O39: 2 | P39: 2 | Q39: 38 | R39: -9 | S39: 0 | T39: 0 | U39: 82400 | V39: =IFERROR(VLOOKUP(D39,Tablas_Equivalencia!$A$3:$B$8,2,FALSE),"Sin dato") | W39: =IFERROR(VLOOKUP(L39,Tablas_Equivalencia!$D$3:$E$9,2,FALSE),"Sin dato") | X39: =IF(I39=1,"Varón","Mujer") | Y39: =IFERROR(VLOOKUP(M39,Tablas_Equivalencia!$G$3:$H$6,2,FALSE),"Sin dato") | Z39: =IF(J39<=24,"18-24","25-29") | AA39: =IF(M39<>1,"",IF(P39=2,1,0)) | AB39: =IF(M39<>1,"",IF(O39>=2,1,0)) | AC39: =IF(M39<>1,"",IF(OR(Q39=999,Q39=""),"",IF(OR(Q39<35,Q39>48),1,0))) | AD39: =IF(COUNT(AA39:AC39)<3,"",SUM(AA39:AC39)) | AE39: =IF(L39>=4,2,IF(L39>=2,1,0)) | AF39: =IF(L39>=5,1,0) | AG39: =AE39+AF39 | AH39: =IF(M39<>1,"",IF(OR(R39=-9,R39=""),"",R39)) | AI39: =IF(M39<>1,"",IF(OR(Q39=999,Q39=""),"",Q39))
A40: TQRMNOP100219 | B40: 2025 | C40: 1 | D40: 1 | E40: S | F40: 33 | G40: 1244 | H40: 3 | I40: 1 | J40: 23 | K40: 2 | L40: 4 | M40: 2 | R40: 0 | S40: 0 | T40: 0 | U40: 68900 | V40: =IFERROR(VLOOKUP(D40,Tablas_Equivalencia!$A$3:$B$8,2,FALSE),"Sin dato") | W40: =IFERROR(VLOOKUP(L40,Tablas_Equivalencia!$D$3:$E$9,2,FALSE),"Sin dato") | X40: =IF(I40=1,"Varón","Mujer") | Y40: =IFERROR(VLOOKUP(M40,Tablas_Equivalencia!$G$3:$H$6,2,FALSE),"Sin dato") | Z40: =IF(J40<=24,"18-24","25-29") | AA40: =IF(M40<>1,"",IF(P40=2,1,0)) | AB40: =IF(M40<>1,"",IF(O40>=2,1,0)) | AC40: =IF(M40<>1,"",IF(OR(Q40=999,Q40=""),"",IF(OR(Q40<35,Q40>48),1,0))) | AD40: =IF(COUNT(AA40:AC40)<3,"",SUM(AA40:AC40)) | AE40: =IF(L40>=4,2,IF(L40>=2,1,0)) | AF40: =IF(L40>=5,1,0) | AG40: =AE40+AF40 | AH40: =IF(M40<>1,"",IF(OR(R40=-9,R40=""),"",R40)) | AI40: =IF(M40<>1,"",IF(OR(Q40=999,Q40=""),"",Q40))
...

Sheet Diagnostico_Nulos
A1: Diagnóstico de valores faltantes y códigos especiales
A2: Tarea 1.3 — conteo de celdas vacías y códigos -9 / 999 sobre el segmento 18-29 años.
A3: Variable | B3: Celdas vacías (no corresponde) | C3: Código especial | D3: Registros con código especial | E3: Válidos para análisis | F3: % válidos sobre jóvenes
A4: P21 | B4: 0 | C4: -9 | D4: 304 | E4: 5629 | F4: 94.9
A5: TOT_P12 | B5: 0 | C5: -9 | D5: 0 | E5: 5933 | F5: 100
A6: PP3E_TOT | B6: 2412 | C6: 999 | D6: 55 | E6: 3466 | F6: 58.4
A7: PP07H | B7: 2412 | C7: — | D7: 0 | E7: 3521 | F7: 59.3
A8: PP07C | B8: 2412 | C8: — | D8: 0 | E8: 3521 | F8: 59.3
A10: Verificación con fórmulas vivas (deben coincidir con la tabla):
A11: Registros totales de la base original | B11: 32000
A12: Jóvenes 18-29 años (CONTARA) | B12: =COUNTA('Jóvenes_18_29'!$A$2:$A$5934)
A13: Jóvenes con CH06 entre 18 y 29 (CONTAR.SI.CONJUNTO) | B13: =COUNTIFS('Jóvenes_18_29'!$J$2:$J$5934,">=18",'Jóvenes_18_29'!$J$2:$J$5934,"<=29")
A14: Ocupados (ESTADO = 1) | B14: =COUNTIF('Jóvenes_18_29'!$M$2:$M$5934,1)
A15: Desocupados (ESTADO = 2) | B15: =COUNTIF('Jóvenes_18_29'!$M$2:$M$5934,2)
A16: Inactivos (ESTADO = 3) | B16: =COUNTIF('Jóvenes_18_29'!$M$2:$M$5934,3)
A17: P21 con código -9 (no respuesta) | B17: =COUNTIF('Jóvenes_18_29'!$R$2:$R$5934,-9)
A18: PP3E_TOT con código 999 (Ns./Nr.) | B18: =COUNTIF('Jóvenes_18_29'!$Q$2:$Q$5934,999)
A19: P21 igual a 0 (sin ingreso por ocupación) | B19: =COUNTIF('Jóvenes_18_29'!$R$2:$R$5934,0)
A21: Tablas de frecuencia de validación (Tareas 2.1 y 2.2)
A22: Valor del índice | B22: Frecuencia IPL | C22: Frecuencia ISE | D22: % IPL sobre ocupados | E22: % ISE sobre jóvenes
A23: 0 | B23: =COUNTIF('Jóvenes_18_29'!$AD$2:$AD$5934,0) | C23: =COUNTIF('Jóvenes_18_29'!$AG$2:$AG$5934,0) | D23: =IFERROR(B23/SUM($B$23:$B$26),0) | E23: =IFERROR(C23/SUM($C$23:$C$26),0)
A24: 1 | B24: =COUNTIF('Jóvenes_18_29'!$AD$2:$AD$5934,1) | C24: =COUNTIF('Jóvenes_18_29'!$AG$2:$AG$5934,1) | D24: =IFERROR(B24/SUM($B$23:$B$26),0) | E24: =IFERROR(C24/SUM($C$23:$C$26),0)
A25: 2 | B25: =COUNTIF('Jóvenes_18_29'!$AD$2:$AD$5934,2) | C25: =COUNTIF('Jóvenes_18_29'!$AG$2:$AG$5934,2) | D25: =IFERROR(B25/SUM($B$23:$B$26),0) | E25: =IFERROR(C25/SUM($C$23:$C$26),0)
A26: 3 | B26: =COUNTIF('Jóvenes_18_29'!$AD$2:$AD$5934,3) | C26: =COUNTIF('Jóvenes_18_29'!$AG$2:$AG$5934,3) | D26: =IFERROR(B26/SUM($B$23:$B$26),0) | E26: =IFERROR(C26/SUM($C$23:$C$26),0)
A27: TOTAL | B27: =SUM(B23:B26) | C27: =SUM(C23:C26)
A28: El total de ISE debe igualar la cantidad de jóvenes; el total de IPL, la cantidad de ocupados con jornada informada (los demás quedan en blanco por diseño).

Sheet Correlacion
A1: Matriz de correlación de Pearson (5 × 5)
A2: Fórmula COEF.DE.CORREL sobre la hoja de trabajo. Los pares con celdas vacías se excluyen automáticamente: el análisis de ingresos y precariedad queda restringido a ocupados.
B3: Edad (CH06) | C3: Ingreso ocup. principal (P21) | D3: Horas semanales (PP3E_TOT) | E3: Precariedad laboral (IPL) | F3: Nivel socio-educativo (ISE)
A4: Edad (CH06) | B4: =CORREL('Jóvenes_18_29'!$J$2:$J$5934,'Jóvenes_18_29'!$J$2:$J$5934) | C4: =CORREL('Jóvenes_18_29'!$J$2:$J$5934,'Jóvenes_18_29'!$AH$2:$AH$5934) | D4: =CORREL('Jóvenes_18_29'!$J$2:$J$5934,'Jóvenes_18_29'!$AI$2:$AI$5934) | E4: =CORREL('Jóvenes_18_29'!$J$2:$J$5934,'Jóvenes_18_29'!$AD$2:$AD$5934) | F4: =CORREL('Jóvenes_18_29'!$J$2:$J$5934,'Jóvenes_18_29'!$AG$2:$AG$5934)
A5: Ingreso ocup. principal (P21) | B5: =CORREL('Jóvenes_18_29'!$AH$2:$AH$5934,'Jóvenes_18_29'!$J$2:$J$5934) | C5: =CORREL('Jóvenes_18_29'!$AH$2:$AH$5934,'Jóvenes_18_29'!$AH$2:$AH$5934) | D5: =CORREL('Jóvenes_18_29'!$AH$2:$AH$5934,'Jóvenes_18_29'!$AI$2:$AI$5934) | E5: =CORREL('Jóvenes_18_29'!$AH$2:$AH$5934,'Jóvenes_18_29'!$AD$2:$AD$5934) | F5: =CORREL('Jóvenes_18_29'!$AH$2:$AH$5934,'Jóvenes_18_29'!$AG$2:$AG$5934)
A6: Horas semanales (PP3E_TOT) | B6: =CORREL('Jóvenes_18_29'!$AI$2:$AI$5934,'Jóvenes_18_29'!$J$2:$J$5934) | C6: =CORREL('Jóvenes_18_29'!$AI$2:$AI$5934,'Jóvenes_18_29'!$AH$2:$AH$5934) | D6: =CORREL('Jóvenes_18_29'!$AI$2:$AI$5934,'Jóvenes_18_29'!$AI$2:$AI$5934) | E6: =CORREL('Jóvenes_18_29'!$AI$2:$AI$5934,'Jóvenes_18_29'!$AD$2:$AD$5934) | F6: =CORREL('Jóvenes_18_29'!$AI$2:$AI$5934,'Jóvenes_18_29'!$AG$2:$AG$5934)
A7: Precariedad laboral (IPL) | B7: =CORREL('Jóvenes_18_29'!$AD$2:$AD$5934,'Jóvenes_18_29'!$J$2:$J$5934) | C7: =CORREL('Jóvenes_18_29'!$AD$2:$AD$5934,'Jóvenes_18_29'!$AH$2:$AH$5934) | D7: =CORREL('Jóvenes_18_29'!$AD$2:$AD$5934,'Jóvenes_18_29'!$AI$2:$AI$5934) | E7: =CORREL('Jóvenes_18_29'!$AD$2:$AD$5934,'Jóvenes_18_29'!$AD$2:$AD$5934) | F7: =CORREL('Jóvenes_18_29'!$AD$2:$AD$5934,'Jóvenes_18_29'!$AG$2:$AG$5934)
A8: Nivel socio-educativo (ISE) | B8: =CORREL('Jóvenes_18_29'!$AG$2:$AG$5934,'Jóvenes_18_29'!$J$2:$J$5934) | C8: =CORREL('Jóvenes_18_29'!$AG$2:$AG$5934,'Jóvenes_18_29'!$AH$2:$AH$5934) | D8: =CORREL('Jóvenes_18_29'!$AG$2:$AG$5934,'Jóvenes_18_29'!$AI$2:$AI$5934) | E8: =CORREL('Jóvenes_18_29'!$AG$2:$AG$5934,'Jóvenes_18_29'!$AD$2:$AD$5934) | F8: =CORREL('Jóvenes_18_29'!$AG$2:$AG$5934,'Jóvenes_18_29'!$AG$2:$AG$5934)
A10: Lectura de los coeficientes significativos (|r| ≥ 0,3)
A11: • ISE ↔ IPL = -0.365: a mayor nivel socio-educativo, menor precariedad laboral. Es la relación más fuerte de la matriz y sostiene la hipótesis central del proyecto.
A12: • ISE ↔ P21 = +0.386: las credenciales educativas se traducen en ingresos ocupacionales más altos.
A13: • IPL ↔ P21 = -0.446: la precariedad opera como penalidad salarial: cada punto de IPL se asocia a menores ingresos.
A14: • Horas ↔ P21 = +0.368: la intensidad horaria explica parte del ingreso, pero menos que las credenciales.
A15: • Edad ↔ P21 = +0.112: dentro de una franja tan estrecha (18-29) la experiencia aporta poco; lo determinante es la calidad del puesto.

Sheet TD_Genero
A1: IPL promedio por sexo y región (tabla dinámica equivalente)
A2: Construida con PROMEDIO.SI.CONJUNTO para que los valores se recalculen solos. En Excel podés reproducirla con Insertar → Tabla dinámica (CH04 en Filas, REGION_TEXTO en Columnas, IPL en Valores como Promedio) y agregarle segmentadores.
A3: Sexo | B3: Gran Buenos Aires | C3: Pampeana | D3: Cuyo | E3: Noroeste (NOA) | F3: Noreste (NEA) | G3: Patagonia | H3: Total país
A4: Varón | B4: =IFERROR(AVERAGEIFS('Jóvenes_18_29'!$AD$2:$AD$5934,'Jóvenes_18_29'!$X$2:$X$5934,$A4,'Jóvenes_18_29'!$V$2:$V$5934,B$3),"s/d") | C4: =IFERROR(AVERAGEIFS('Jóvenes_18_29'!$AD$2:$AD$5934,'Jóvenes_18_29'!$X$2:$X$5934,$A4,'Jóvenes_18_29'!$V$2:$V$5934,C$3),"s/d") | D4: =IFERROR(AVERAGEIFS('Jóvenes_18_29'!$AD$2:$AD$5934,'Jóvenes_18_29'!$X$2:$X$5934,$A4,'Jóvenes_18_29'!$V$2:$V$5934,D$3),"s/d") | E4: =IFERROR(AVERAGEIFS('Jóvenes_18_29'!$AD$2:$AD$5934,'Jóvenes_18_29'!$X$2:$X$5934,$A4,'Jóvenes_18_29'!$V$2:$V$5934,E$3),"s/d") | F4: =IFERROR(AVERAGEIFS('Jóvenes_18_29'!$AD$2:$AD$5934,'Jóvenes_18_29'!$X$2:$X$5934,$A4,'Jóvenes_18_29'!$V$2:$V$5934,F$3),"s/d") | G4: =IFERROR(AVERAGEIFS('Jóvenes_18_29'!$AD$2:$AD$5934,'Jóvenes_18_29'!$X$2:$X$5934,$A4,'Jóvenes_18_29'!$V$2:$V$5934,G$3),"s/d") | H4: =AVERAGEIF('Jóvenes_18_29'!$X$2:$X$5934,$A4,'Jóvenes_18_29'!$AD$2:$AD$5934)
A5: Mujer | B5: =IFERROR(AVERAGEIFS('Jóvenes_18_29'!$AD$2:$AD$5934,'Jóvenes_18_29'!$X$2:$X$5934,$A5,'Jóvenes_18_29'!$V$2:$V$5934,B$3),"s/d") | C5: =IFERROR(AVERAGEIFS('Jóvenes_18_29'!$AD$2:$AD$5934,'Jóvenes_18_29'!$X$2:$X$5934,$A5,'Jóvenes_18_29'!$V$2:$V$5934,C$3),"s/d") | D5: =IFERROR(AVERAGEIFS('Jóvenes_18_29'!$AD$2:$AD$5934,'Jóvenes_18_29'!$X$2:$X$5934,$A5,'Jóvenes_18_29'!$V$2:$V$5934,D$3),"s/d") | E5: =IFERROR(AVERAGEIFS('Jóvenes_18_29'!$AD$2:$AD$5934,'Jóvenes_18_29'!$X$2:$X$5934,$A5,'Jóvenes_18_29'!$V$2:$V$5934,E$3),"s/d") | F5: =IFERROR(AVERAGEIFS('Jóvenes_18_29'!$AD$2:$AD$5934,'Jóvenes_18_29'!$X$2:$X$5934,$A5,'Jóvenes_18_29'!$V$2:$V$5934,F$3),"s/d") | G5: =IFERROR(AVERAGEIFS('Jóvenes_18_29'!$AD$2:$AD$5934,'Jóvenes_18_29'!$X$2:$X$5934,$A5,'Jóvenes_18_29'!$V$2:$V$5934,G$3),"s/d") | H5: =AVERAGEIF('Jóvenes_18_29'!$X$2:$X$5934,$A5,'Jóvenes_18_29'!$AD$2:$AD$5934)
A6: Brecha (Mujer − Varón) | B6: =IFERROR(B5-B4,"s/d") | C6: =IFERROR(C5-C4,"s/d") | D6: =IFERROR(D5-D4,"s/d") | E6: =IFERROR(E5-E4,"s/d") | F6: =IFERROR(F5-F4,"s/d") | G6: =IFERROR(G5-G4,"s/d") | H6: =IFERROR(H5-H4,"s/d")
A8: Ingreso promedio (P21) por sexo y brecha de ingresos
A9: Sexo | B9: Ingreso promedio | C9: Casos válidos | D9: Horas promedio | E9: % informalidad
A10: Varón | B10: =AVERAGEIF('Jóvenes_18_29'!$X$2:$X$5934,$A10,'Jóvenes_18_29'!$AH$2:$AH$5934) | C10: =COUNTIFS('Jóvenes_18_29'!$X$2:$X$5934,$A10,'Jóvenes_18_29'!$AH$2:$AH$5934,">0") | D10: =AVERAGEIF('Jóvenes_18_29'!$X$2:$X$5934,$A10,'Jóvenes_18_29'!$AI$2:$AI$5934) | E10: =AVERAGEIF('Jóvenes_18_29'!$X$2:$X$5934,$A10,'Jóvenes_18_29'!$AA$2:$AA$5934)
A11: Mujer | B11: =AVERAGEIF('Jóvenes_18_29'!$X$2:$X$5934,$A11,'Jóvenes_18_29'!$AH$2:$AH$5934) | C11: =COUNTIFS('Jóvenes_18_29'!$X$2:$X$5934,$A11,'Jóvenes_18_29'!$AH$2:$AH$5934,">0") | D11: =AVERAGEIF('Jóvenes_18_29'!$X$2:$X$5934,$A11,'Jóvenes_18_29'!$AI$2:$AI$5934) | E11: =AVERAGEIF('Jóvenes_18_29'!$X$2:$X$5934,$A11,'Jóvenes_18_29'!$AA$2:$AA$5934)
A12: Brecha de ingresos (1 − Mujer/Varón) | B12: =IFERROR(1-B11/B10,"s/d")

Sheet Ingreso_Educacion
A1: Ingreso y precariedad según nivel educativo
A2: Tarea 4.1 — PROMEDIO.SI sobre NIVEL_ED. Base: jóvenes ocupados con ingreso informado.
A3: Código | B3: Nivel educativo | C3: Ingreso promedio (P21) | D3: Casos válidos | E3: IPL promedio | F3: % informalidad
A4: 1 | B4: Primaria incompleta | C4: =IFERROR(AVERAGEIF('Jóvenes_18_29'!$L$2:$L$5934,$A4,'Jóvenes_18_29'!$AH$2:$AH$5934),0) | D4: =COUNTIFS('Jóvenes_18_29'!$L$2:$L$5934,$A4,'Jóvenes_18_29'!$AH$2:$AH$5934,">0") | E4: =IFERROR(AVERAGEIF('Jóvenes_18_29'!$L$2:$L$5934,$A4,'Jóvenes_18_29'!$AD$2:$AD$5934),0) | F4: =IFERROR(AVERAGEIF('Jóvenes_18_29'!$L$2:$L$5934,$A4,'Jóvenes_18_29'!$AA$2:$AA$5934),0)
A5: 2 | B5: Primaria completa | C5: =IFERROR(AVERAGEIF('Jóvenes_18_29'!$L$2:$L$5934,$A5,'Jóvenes_18_29'!$AH$2:$AH$5934),0) | D5: =COUNTIFS('Jóvenes_18_29'!$L$2:$L$5934,$A5,'Jóvenes_18_29'!$AH$2:$AH$5934,">0") | E5: =IFERROR(AVERAGEIF('Jóvenes_18_29'!$L$2:$L$5934,$A5,'Jóvenes_18_29'!$AD$2:$AD$5934),0) | F5: =IFERROR(AVERAGEIF('Jóvenes_18_29'!$L$2:$L$5934,$A5,'Jóvenes_18_29'!$AA$2:$AA$5934),0)
A6: 3 | B6: Secundaria incompleta | C6: =IFERROR(AVERAGEIF('Jóvenes_18_29'!$L$2:$L$5934,$A6,'Jóvenes_18_29'!$AH$2:$AH$5934),0) | D6: =COUNTIFS('Jóvenes_18_29'!$L$2:$L$5934,$A6,'Jóvenes_18_29'!$AH$2:$AH$5934,">0") | E6: =IFERROR(AVERAGEIF('Jóvenes_18_29'!$L$2:$L$5934,$A6,'Jóvenes_18_29'!$AD$2:$AD$5934),0) | F6: =IFERROR(AVERAGEIF('Jóvenes_18_29'!$L$2:$L$5934,$A6,'Jóvenes_18_29'!$AA$2:$AA$5934),0)
A7: 4 | B7: Secundaria completa | C7: =IFERROR(AVERAGEIF('Jóvenes_18_29'!$L$2:$L$5934,$A7,'Jóvenes_18_29'!$AH$2:$AH$5934),0) | D7: =COUNTIFS('Jóvenes_18_29'!$L$2:$L$5934,$A7,'Jóvenes_18_29'!$AH$2:$AH$5934,">0") | E7: =IFERROR(AVERAGEIF('Jóvenes_18_29'!$L$2:$L$5934,$A7,'Jóvenes_18_29'!$AD$2:$AD$5934),0) | F7: =IFERROR(AVERAGEIF('Jóvenes_18_29'!$L$2:$L$5934,$A7,'Jóvenes_18_29'!$AA$2:$AA$5934),0)
A8: 5 | B8: Superior incompleto | C8: =IFERROR(AVERAGEIF('Jóvenes_18_29'!$L$2:$L$5934,$A8,'Jóvenes_18_29'!$AH$2:$AH$5934),0) | D8: =COUNTIFS('Jóvenes_18_29'!$L$2:$L$5934,$A8,'Jóvenes_18_29'!$AH$2:$AH$5934,">0") | E8: =IFERROR(AVERAGEIF('Jóvenes_18_29'!$L$2:$L$5934,$A8,'Jóvenes_18_29'!$AD$2:$AD$5934),0) | F8: =IFERROR(AVERAGEIF('Jóvenes_18_29'!$L$2:$L$5934,$A8,'Jóvenes_18_29'!$AA$2:$AA$5934),0)
A9: 6 | B9: Superior completo | C9: =IFERROR(AVERAGEIF('Jóvenes_18_29'!$L$2:$L$5934,$A9,'Jóvenes_18_29'!$AH$2:$AH$5934),0) | D9: =COUNTIFS('Jóvenes_18_29'!$L$2:$L$5934,$A9,'Jóvenes_18_29'!$AH$2:$AH$5934,">0") | E9: =IFERROR(AVERAGEIF('Jóvenes_18_29'!$L$2:$L$5934,$A9,'Jóvenes_18_29'!$AD$2:$AD$5934),0) | F9: =IFERROR(AVERAGEIF('Jóvenes_18_29'!$L$2:$L$5934,$A9,'Jóvenes_18_29'!$AA$2:$AA$5934),0)

Sheet Bitacora
A1: Bitácora de decisiones metodológicas
A2: Toda decisión que altera los resultados queda documentada y es auditable.
A3: # | B3: Decisión | C3: Fundamento | D3: Impacto en los resultados
A4: 1 | B4: Universo: 18 a 29 años cumplidos (CH06) | C4: Definición de juventud usada por los programas de primer empleo; excluye adolescentes escolarizados obligatorios. | D4: Quedan 5,933 de 32,000 registros (18.5% de la muestra).
A5: 2 | B5: No se eliminan los casos con P21 = 0 | C5: Un ingreso cero no es un error: identifica a desocupados e inactivos, población central del diagnóstico. | D5: Se conserva la estructura real del segmento; los promedios de ingreso se calculan solo sobre ocupados.
A6: 3 | B6: P21 = -9 y PP3E_TOT = 999 se tratan como faltantes, no como ceros | C6: Son códigos de no respuesta del INDEC; computarlos como valores hundiría artificialmente los promedios. | D6: Se excluyen 304 ingresos y 55 jornadas.
A7: 4 | B7: Las columnas P21_LIMPIO y HORAS_LIMPIO alimentan la matriz de correlación | C7: COEF.DE.CORREL descarta los pares con texto o vacío: así el coeficiente se calcula sobre casos válidos. | D7: Evita el sesgo de incluir ceros estructurales en las correlaciones de ingreso.
A8: 5 | B8: IPL en blanco para quienes no están ocupados (ESTADO ≠ 1) | C8: PP07H y PP07C solo se relevan a ocupados; asignarles 0 los contaría como empleo de calidad. | D8: El IPL se calcula sobre 3,466 ocupados con jornada informada.
A9: 6 | B9: Umbrales del IPL: sin aportes (PP07H=2), inestabilidad (PP07C≥2), jornada <35 h o >48 h | C9: Replican los criterios de informalidad, temporalidad y sub/sobreocupación usados en la literatura del mercado laboral. | D9: IPL promedio = 1.72; 32.9% de los ocupados acumula las tres carencias.
A10: 7 | B10: ISE: 2 puntos por secundaria completa o más, 1 punto extra por estudios superiores | C10: Discrimina el salto de credenciales que el mercado premia; mantiene una escala comparable con el IPL (0 a 3). | D10: Correlación ISE ↔ IPL = -0.365.
A11: 8 | B11: Se conserva una copia intacta del archivo original | C11: Trazabilidad: cualquier resultado debe poder reproducirse desde el dato crudo. | D11: 01_Datos_Originales/ nunca se modifica; todo el trabajo ocurre en 02_Datos_Procesados/.
A12: 9 | B12: Base de trabajo SIMULADA con la estructura oficial de la EPH | C12: El entorno de ejecución no tiene acceso al portal del INDEC; se generó una base con los mismos nombres y códigos. | D12: Las fórmulas, el dashboard y el informe son válidos; los valores se actualizan al reemplazar el .txt por el oficial.
